#### 简介

是一种异步解决方案，替代之前的`回调函数`和`事件`(同时另外两个`Generator`和 `async/await`)

所谓`Promise`,像是一个容器，里面保存着未来才会结束的事件(通常是一个异步操作)的结果，`Promise`是一个对象，从它可以获取异步操作的消息。（像Axios拦截器，Koa调用中间件，Redux调用中间件都是利用了Promise）

三种状态：  
`pending:` 异步操作执行中   

`fulfilled:` 异步执行成功

`rejected:` 异步操作执行失败

<br/>

#### 基本使用
~~~js
const request = (method, url, data) => {
  return new Promise((resolve, reject) => {
    // promise中的异步请求
    const xhr = new XMLHttpRequest();
    xhr.open(method, url, true);
    xhr.responseType = 'json';
    xhr.onreadystatechange = () => {
      if (xhr.readyState === XMLHttpRequest.DONE && xhr.status === 200) {
        resolve(xhr.response);
      } else {
        reject(new Error(xhr.responseText));
      }
    };
    xhr.send('post' === method ? data : null);
  });
};

// then中两个回调函数参数resolve状态回调, reject状态回调
request('get', './package.json').then((result) => {
  console.log(result);
}, (error) => {
  console.log(error.message);
});
~~~

promise嵌套：  

~~~js
const p1 = new Promise((resolve, reject) => {
  reject();
});

const p2 = new Promise((resolve, reject) => {
  resolve(p1);
});

p2.then((data) => {
  console.log('resolve');
}, (data) => {
  console.log('reject');
});

// node环境使用catch()捕获异常
p2.then((data) => {
  console.log('resolve');
}).catch((data) => {
  console.log('reject');
});
~~~
报错：`[DEP0018] DeprecationWarning: Unhandled promise rejections are deprecated. In the future, promise rejections 
that are not handled will terminate the Node.js process with a non-zero exit code.`

> 在 Node.js 6.6.0 中增加了一个特性：对 Promise 中未处理的 rejection 默认会输出 UnhandledPromiseRejectionWarning 提示,  同时也会触发node中的unhandledRejection事件

> 在浏览器环境中上面会输出reject

<br/>

#### Promise.prototype.then()

作用：为Promise实例添加状态改变时的回调函数，then()方法的第一个参数是resolved状态的回调函数，第二个是rejected状态的回调函数。

`then()方法返回的是一个Promise(不是实例Promise)，因此可以采用链式调用，then方法后跟then方法`


~~~js
/**
* 自己实现Promise类时，注意then()方法接受一个函数，返回一个Promise，函数的返回值
* 会作为Promise的resolve()值
*/
const p = new Promise((resolve, reject) => {
  resolve('data');
});

p.then((data) => {
  console.log(data);
  return 'data1';
}).then((data) => {
  console.log(data);
  return 'data2';
}).then((data) => {
  console.log(data);
});
~~~

#### Promise.prototype.catch()

`Promise.prototype.catch`是`.then(null, rejected)`或`.then(undefined, rejected)`的别名，用于指定发生错误时的回调。

~~~js
// catch可以捕获getJSON()和then()方法内的错误
getJSON('/posts.json').then(function(posts) {
  // ...
}).catch(function(error) {
  // 处理 getJSON 和 前一个回调函数运行时发生的错误
  console.log('发生错误！', error);
});
~~~

Promise 对象的错误具有“冒泡”性质，会一直向后传递，直到被捕获为止。也就是说，错误总是会被下一个`catch`语句捕获。

一般来说，不要在`then()`方法里面定义 Reject 状态的回调函数（即then的第二个参数），总是使用`catch()`方法。

<br/>


#### Promise.prototype.finally()

> `finally()`方法用于指定不管 Promise 对象最后状态如何，都会执行的操作。该方法是 ES2018 引入标准的。
~~~js
promise
.then(result => {···})
.catch(error => {···})
.finally(() => {···});
~~~

`finally`方法的回调函数不接受任何参数，这意味着没有办法知道，前面的 Promise 状态到底是`fulfilled`还是`rejected`。这表明，finally方法里面的操作，应该是与状态无关的，不依赖于 Promise 的执行结果。

<br/>

#### Promise.resolve()

将现有对象转化为Promise对象  

`Promise.resolve()`的参数有四种情况：

1、参数是一个`Promise实例  `

直接原封不动的返回promise实例
~~~js
const p = new Promise((resolve, reject) => {
  setTimeout(() => {
    resolve('dong');
  }, 1000);
});

Promise.resolve(p).then((data) => {
  console.log(data);
});
~~~

2、参数是一个`thenable对象`

`thenable`对象是指具有`then`方法的对象   

`Promise.resolve()`将这个对象转化为Promise对象，并立即调用改对象的`then`方法

~~~js
const thenable = {
  then(resolve, reject) {
    setTimeout(() => {
      resolve('dong');
    }, 1000);
  }
}

Promise.resolve(thenable).then((data) => {
  console.log(data);
});

.............................

class Thenable {
  then(resolve, reject){
    resolve('dong');
  }
}

const th = new Thenable();

Promise.resolve(th).then((data) => {
  console.log(data);
});
~~~

3、参数是不具有`then`方法的对象，或者根本不是一个对象  

如果参数是一个原始值，或者是一个不具有then()方法的对象，则`Promise.resolve()`方法返回一个新的 Promise 对象，状态为`resolved`。

~~~js
// 参数为函数，原始值，不具有then方法的对象都直接resolve
Promise.resolve(() => {
  return 'dong';
}).then((data) => {
  console.log(data);
});

// [Function]
~~~

4、不带任何参数  

直接返回一个`resolved`状态的Promise对象  

* `Promise.resolve()` 是在本轮`事件循环`的结束时执行
* `setTimeout(fn, 0)` 时在下一轮`事件循环`开始执行
* 执行顺序:  `同步` > `Promise.resolve()` > `setTimeout(fn, 0)`

~~~js
Promise.resolve().then(() => {
  console.log('promise');
});

setTimeout(() => {
  console.log('settimeout');
}, 0);

console.log('sync');

/** 输出结果
sync
promise
settimeout
*/
~~~

<br/>

#### Promise.reject()  

`Promise.reject(reason)`方法会返回一个新的Promise实例，改实例的状态为`rejected`

`Promise.reject()`方法的参数，会原封不动地作为reject的理由，变成后续方法的参数。

~~~js
Promise.reject('出错了')
.catch(e => {
  console.log(e === '出错了')
})
~~~

<br/>

#### Promise.all()

`Promise.all()` 方法用于将多个Promise实例，包装成一个新的Promise实例

~~~js
const p = Promise.all([p1, p2, p3]); // p1, p2, p3 分别为Promise实例
~~~

`p`的状态由`p1`,`p2`,`p3`来决定，分两种情况：

* 当`p1`,`p2`,`p3`的状态都变成`fulfilled`,`p`的状态才变成`fulfilled`,此时`p1`,`p2`,`p3`的返回值组成一个数组，传递给`p`的回调函数

* 当`p1`, `p2`, `p3`有一个被`reject`, `p`的状态才变成`rejected`,此时第一个被`reject`的实例返回值，会传递给`p`的回调函数。

~~~js
// 虽然p2先resolve(), 但是p1时rejected的，因此p的状态为rejected, 将p1的返回值，传递给p的rejected状态回调函数
const p1 = new Promise((resolve, reject) => {
  setTimeout(() => {
    reject('p1');
  }, 2000);
});

const p2 = new Promise((resolve, reject) => {
  setTimeout(() => {
    resolve('p2');
  }, 1000);
});

const set = new Set();

set.add(p1);
set.add(p2);

const p = Promise.all(set);

p.then((data) => {
  console.log(data);
}).catch((err) => {
  console.log(err);
});

// p1
~~~

~~~js
const p1 = new Promise((resolve, reject) => {
  resolve('hello');
});

const p2 = new Promise((resolve, reject) => {
  throw new Error('报错了');
})
.then(result => result)
.catch(e => e);

Promise.all([p1, p2])
.then(result => console.log(result))
.catch(e => console.log(e));

/*
[
  'hello',
  Error: 报错了
      at E:\node-demo\server.js:6:9
      at new Promise (<anonymous>)
      at Object.<anonymous> (E:\node-demo\server.js:5:12)
      at Module._compile (internal/modules/cjs/loader.js:959:30)
      at Object.Module._extensions..js (internal/modules/cjs/loader.js:995:10)
      at Module.load (internal/modules/cjs/loader.js:815:32)
      at Function.Module._load (internal/modules/cjs/loader.js:727:14)
      at Function.Module.runMain (internal/modules/cjs/loader.js:1047:10)
      at internal/main/run_main_module.js:17:11
]
*/

/**
p1 resove, p2首先会reject, 但是p2有自己的catch方法，catch方法返回新的Promise，p2指向的其实是这个实例，改catch实例执行完catch方法后，会变成resolve，导致Promise.all()方法参数里面的两个实例都会resolved，因此会调用then方法指定的回调函数，而不会调用catch方法指定的回调函数。
*/
~~~

<br/>

#### Promise.race()

`Promise.race()`同样是将多个Promise实例包装成一个Promise实例。

~~~js
const p = Promise.race([p1, p2, p3]);
~~~

上面代码中，只要`p1`, `p2`, `p3`之中有一个实例率先改变状态，`p`的状态就跟着改变。那个率先改变的 Promise 实例的返回值，就传递给`p`的回调函数。

> 超时实例
~~~js
const p = Promise.race([fetch('./index.html'), new Promise((resolve, reject) => {
  setTimeout(() => {
    reject(new Error('request timeout'));
  }, 3000);
})]);

p.then(result => result).catch(e => e);
~~~

> 应用实例
~~~js
// 返回一个promise
function fetchShortUrl(url, method, params) {
  return Promise.race([
    window.fetch(url, {
      method: method?? 'get',
      headers: {
        'content-type': 'application/json',
      },
      body: JSON.stringify(params),
    }).then((res) => {
      if (res.ok) {
        return res;
      }
      return Promise.reject(`${res.status}(${res.statusText})`);
    }).catch(error => Promise.reject(String(error))),
    new Promise(((resolve, reject) => {
      setTimeout(() => {
        reject(intl.get('REQUEST_TIMEOUT'));
      }, 20000);
    }))])
    .then(response => response.json())
    .then(async (data) => {
      if (Number(data.Code) === 0) {
        return data;
      }
      return Promise.reject(data.ErrMsg);
    }).catch((error) => {
      message.error(error, 3);
      return Promise.reject(error);
    });
}
~~~


#### Promise.allSettled()

`Promise.allSettled()`方法接受一组Promise实例作为参数，包装成一个新的Promise实例，只有等所有这些参数实例都返回结果，不管是`fulfilled`还是`rejected`,包装实例才会结束。

改方法返回的新的Promise实例，一旦结束，状态总是`fulfilled`，不会变成`rejected`,状态`fulfilled`后，Promise的监听函数接收的参数是一个数组，每个成员对应一个传入`Promise.allSettled()`的Promise实例。

~~~js
const resolved = Promise.resolve(42);
const rejected = Promise.reject(-1);

const allSettledPromise = Promise.allSettled([resolved, rejected]);

allSettledPromise.then(function (results) {
  console.log(results);
});
/**
[
  { status: 'fulfilled', value: 42 },
  { status: 'rejected', reason: -1 } 
]
*/
~~~

#### Promise.any()

`Promise.any()`接受一组Promise实例作为参数，包装成新的Promise实例返回，只要参数实例有一个变成`fulfilled`状态，包装实例才变成`fulfilled`,如果所有参数都变成`rejected`状态，包装实例就会变成`rejected`状态。


https://zhuanlan.zhihu.com/p/35697919
https://segmentfault.com/a/1190000016411620)%E4%B8%AD