#### 基本概念

ES2017 新增的异步API，是Generator函数的语法糖。

~~~js
const gen = function* () {
  const f1 = yield readFile('/etc/fstab');
  const f2 = yield readFile('/etc/shells');
  console.log(f1.toString());
  console.log(f2.toString());
};

// async写法
const gen = async function  () {
  const f1 = await readFile('/etc/fstab');
  const f2 = await readFile('/etc/shells');
  console.log(f1.toString());
  console.log(f2.toString());
};
~~~

`async`函数就是将Generator函数的星号`*`替换成了`async`,将`yield`替换成了`await`

`async`函数比`Generator`函数改进的四个方面：

* 内置执行器  

Generator函数必须依靠外部的执行器，比如`co`模块，而`async`函数自带执行器。

* 更好的语义  

* 更广的适用性

`co`模块约定，`yield`命令后面必须为Thunk函数或者Promise对象  

`async`函数的`await`命令后，可以是Promise对象和原始值(原始值会立刻resolve)

* 返回值是promise

`async`函数的返回值是Promise，这比Generator函数的返回值`遍历器对象`方便多，进一步说，`async`函数完全可以看成，多个异步操作
包装成的一个Promise，而`await`命令就是内部`then`命令的语法糖。

<br/>

#### 基本使用

~~~js
// 函数声明
async function foo() {}

// 函数表达式
const foo = async function () {};

// 对象的方法
let obj = { async foo() {} };
obj.foo().then(...)

// Class 的方法
class Storage {
  constructor() {
    this.cachePromise = caches.open('avatars');
  }

  async getAvatar(name) {
    const cache = await this.cachePromise;
    return cache.match(`/avatars/${name}.jpg`);
  }
}

const storage = new Storage();
storage.getAvatar('jake').then(…);

// 箭头函数
const foo = async () => {};
~~~

<br/>

#### 语法

* `async`函数返回一个promise对象  

* `async`函数内部的`return`语句的返回值，会成为`then`方法回调函数的参数

* `async`函数内部抛出的错误，会导致返回的promise对象状态变为`reject`, 被`catch`方法的回调函数接收到。

* 正常情况下，`await`命令后面是一个promise对象，返回改对象的执行结果，如果不是promise直接返回。

~~~js
const func = async () => {
  const val = await new Promise((resolve, reject) => {
    setTimeout(() => {
      resolve('dong');
    }, 2000);
  });
  console.log(val);
  return val;
}

func().then(data => {
  console.log(data);
})
// dong dong
~~~


##### await命令

任何一个`await语句`后面的 Promise 对象变为`reject`状态，那么整个async函数都会`中断执行`。

~~~js
const func = async () => {
  const t1 = await Promise.resolve('1');
  const t2 = await Promise.reject('2');
  const t3 = await Promise.resolve('3');
  console.log(t1);
  console.log(t2);
  console.log(t3);
}

func().then(() => {
  console.log('then');
}).catch(() => {
  console.log('error')
});
// error
// 只要有一个await后面的promise rejected，则async立刻结束代码执行，状态变成rejected,调用catch()中的回调函数。
~~~

<br/>

#### 错误处理

两种错误处理方式：

1、await 放在`try ... catch`代码块中。
~~~js
const func = async () => {
  const t1 = await Promise.resolve('1');
  let t2 = '';
  try {
    t2 = await Promise.reject('2');
  } catch(e) {
    console.log(e);
  }
  const t3 = await Promise.resolve('3');
  console.log(t1);
  console.log(t2);
  console.log(t3);
}

func().then(() => {
  console.log('then');
}).catch(() => {
  console.log('error')
});
/**
2
1

3
then
*/
~~~

2、promise添加`catch`捕获异常

~~~js
const func = async () => {
  const t1 = await Promise.resolve('1');
  const t2 = await Promise.reject('2').catch(() => {
    console.log('2');
  });
  const t3 = await Promise.resolve('3');
  console.log(t1);
  console.log(t2);
  console.log(t3);
}

func().then(() => {
  console.log('then');
}).catch(() => {
  console.log('error')
});
/**
2
1
undefined
3
then
*/
~~~